<mujoco model="panda">

<default>
    <joint type="hinge" limited="true" frictionloss="5000" />
    <!--position ctrllimited="true" ctrlrange="-1.57 1.57" forcelimited="true" forcerange="-7 7" kp="15" /-->
</default>
  <compiler angle="radian" meshdir="all_mesh/"/>
  <asset>
    <mesh name="link0" file="link0.obj"/>
    <mesh name="link1_v" file="link1_v.obj"/>
    <mesh name="link1" file="link1.obj"/>
    <mesh name="link2_v" file="link2_v.obj"/>
    <mesh name="link2" file="link2.obj"/>
    <mesh name="link3_v" file="link3_v.obj"/>
    <mesh name="link3" file="link3.obj"/>
    <mesh name="link4_v" file="link4_v.obj"/>
    <mesh name="link4" file="link4.obj"/>
    <mesh name="link5_v" file="link5_v.obj"/>
    <mesh name="link5" file="link5.obj"/>
    <mesh name="link6_v" file="link6_v.obj"/>
    <mesh name="link6" file="link6.obj"/>
    <mesh name="link7" file="link7.obj"/>
    <mesh name="hand_v" file="hand_v.obj"/>
    <mesh name="hand" file="hand.obj"/>
    <mesh name="finger_v" file="finger_v.obj"/>
    <mesh name="finger" file="finger.obj"/>
  </asset>
  <worldbody>
    <body name="base" pos="-0.4 0.6 0">
      <geom type="mesh" contype="0" conaffinity="0" group="1" density="0" rgba="1 1 1 1" mesh="link0"/>
      <geom type="mesh" rgba="1 1 1 1" mesh="link0"/>
      <body name="panda_link1" pos="0 0 0.333">
        <inertial pos="0 -0.04 -0.05" mass="2.7" diaginertia="0.1 0.1 0.1"/>
        <joint name="panda_joint1" pos="0 0 0" axis="0 0 1" range="-2.9671 2.9671" />
        <geom type="mesh" contype="0" conaffinity="0" group="1" density="0" rgba="1 1 1 1" mesh="link1_v"/>
        <geom type="mesh" rgba="1 1 1 1" mesh="link1"/>
        <body name="panda_link2" quat="0.707107 -0.707107 0 0">
          <inertial pos="0 -0.04 0.06" mass="2.73" diaginertia="0.1 0.1 0.1"/>
          <joint name="panda_joint2" pos="0 0 0" axis="0 0 1" range="-1.8326 1.8326"/>
          <geom type="mesh" contype="0" conaffinity="0" group="1" density="0" rgba="1 1 1 1" mesh="link2_v"/>
          <geom type="mesh" rgba="1 1 1 1" mesh="link2"/>
          <body name="panda_link3" pos="0 -0.316 0" quat="0.707107 0.707107 0 0">
            <inertial pos="0.01 0.01 -0.05" mass="2.04" diaginertia="0.1 0.1 0.1"/>
            <joint name="panda_joint3" pos="0 0 0" axis="0 0 1" range="-2.9671 2.9671"/>
            <geom type="mesh" contype="0" conaffinity="0" group="1" density="0" rgba="1 1 1 1" mesh="link3_v"/>
            <geom type="mesh" rgba="1 1 1 1" mesh="link3"/>
            <body name="panda_link4" pos="0.0825 0 0" quat="0.707107 0.707107 0 0">
              <inertial pos="-0.03 0.03 0.02" mass="2.08" diaginertia="0.1 0.1 0.1"/>
              <joint name="panda_joint4" pos="0 0 0" axis="0 0 1" range="-3.1416 0"/>
              <geom type="mesh" contype="0" conaffinity="0" group="1" density="0" rgba="1 1 1 1" mesh="link4_v"/>
              <geom type="mesh" rgba="1 1 1 1" mesh="link4"/>
              <body name="panda_link5" pos="-0.0825 0.384 0" quat="0.707107 -0.707107 0 0">
                <inertial pos="0 0.04 -0.12" mass="3" diaginertia="0.1 0.1 0.1"/>
                <joint name="panda_joint5" pos="0 0 0" axis="0 0 1" range="-2.9671 2.9671"/>
                <geom type="mesh" contype="0" conaffinity="0" group="1" density="0" rgba="1 1 1 1" mesh="link5_v"/>
                <geom type="mesh" rgba="1 1 1 1" mesh="link5"/>
                <body name="panda_link6" quat="0.707107 0.707107 0 0">
                  <inertial pos="0.04 0 0" mass="1.3" diaginertia="0.1 0.1 0.1"/>
                  <joint name="panda_joint6" pos="0 0 0" axis="0 0 1" range="-0.0873 3.8223"/>
                  <geom type="mesh" contype="0" conaffinity="0" group="1" density="0" rgba="1 1 1 1" mesh="link6_v"/>
                  <geom type="mesh" rgba="1 1 1 1" mesh="link6"/>
                  <body name="panda_link7" pos="0.088 0 0" quat="0.707107 0.707107 0 0">
                    <inertial pos="0 0 0.133733" mass="1.01" diaginertia="0.20072 0.20072 0.2"/>
                    <joint name="panda_joint7" pos="0 0 0" axis="0 0 1" range="-2.9671 2.9671"/>
                    <geom type="mesh" contype="0" conaffinity="0" group="1" density="0" rgba="1 1 1 1" mesh="link7"/>
                    <geom type="mesh" rgba="1 1 1 1" mesh="link7"/>
                    <geom pos="0 0 0.107" quat="0.92388 0 0 -0.382683" type="mesh" contype="0" conaffinity="0" group="1" density="0" rgba="1 1 1 1" mesh="hand_v"/>
                    <geom pos="0 0 0.107" quat="0.92388 0 0 -0.382683" type="mesh" rgba="1 1 1 1" mesh="hand"/>
                    <body name="panda_leftfinger" pos="0 0 0.1654" quat="0.92388 0 0 -0.382683">
                      <inertial pos="0 0.01 0.02" mass="0.1" diaginertia="0.1 0.1 0.1"/>
                      <joint name="panda_finger_joint1" pos="0 0 0" axis="0 1 0" type="slide" range="0 0.04"/>
                      <geom type="mesh" contype="0" conaffinity="0" group="1" density="0" rgba="1 1 1 1" mesh="finger_v" name="left_finger"/>
                      <geom type="mesh" rgba="1 1 1 1" mesh="finger"/>
                    </body>
                    <body name="panda_rightfinger" pos="0 0 0.1654" quat="0.92388 0 0 -0.382683">
                      <inertial pos="0 -0.01 0.02" mass="0.1" diaginertia="0.1 0.1 0.1"/>
                      <joint name="panda_finger_joint2" pos="0 0 0" axis="0 -1 0" type="slide" range="0 0.04"/>
                      <geom quat="0 0 0 1" type="mesh" contype="0" conaffinity="0" group="1" density="0" rgba="1 1 1 1" mesh="finger_v" name="right_finger"/>
                      <geom quat="0 0 0 1" type="mesh" rgba="1 1 1 1" mesh="finger"/>
                    </body>
                  </body>
                </body>
              </body>
            </body>
          </body>
        </body>
      </body>
    </body>
  </worldbody>
</mujoco>
